<?xml version='1.0'?>
<sdf version='1.4'>
  <model name='robomagellan_2024'>
    <!-- If static is true, the physics engine will ignore this model -->
    <static>false</static>

    <!--
      Main chassis frame.  This will be represented by a box with the following
      dimensions:

      Length: 31.5 inches -> 0.8 meters
      Width: 25 inches -> 0.635 meters
      Height: 2 inches -> 0.0508 meters

      Gazebo expects dimensions to be given in meters.
    -->
    <link name='chassis'>
      <!--
        The wheels are 6" diameter wheels; at a position of (0, 0, 0) the
        chassis sits on the ground plane.  Therefore the chassis must be offset
        by 3" - (2" / 2) = 2" -> 0.0508 meters.
      -->
      <pose>0 0 0.0762 0 0 0</pose>

      <!--
        The chassis will be represented with a cuboid with the above dimensions
        and a weight of 50 lbs (the max limit allowed).
      -->
      <inertial>
        <mass>22.68</mass>
        <inertia>
          <ixx>0.767</ixx>
          <iyy>1.2145</iyy>
          <izz>1.9717</izz>
          <ixy>0</ixy>
          <ixz>0</ixz>
          <iyz>0</iyz>
        </inertia>
      </inertial>

      <!--
        Side beams.  Centered around the origin.

        Dimensions:
        Length: 29.5 inches -> 0.7493 meters
        Width: 1 inch -> 0.0254 meters
        Height: 2 inches -> 0.0508 meters
      -->
      <collision name='left_side_collision'>
        <pose>0 0.20955 0 0 0 0</pose>
        <geometry>
          <box>
            <size>0.7493 0.0254 0.0508</size>
          </box>
        </geometry>
      </collision>

      <visual name='left_side_visual'>
        <pose>0 0.20955 0 0 0 0</pose>
        <geometry>
          <box>
            <size>0.7493 0.0254 0.0508</size>
          </box>
        </geometry>
      </visual>

      <collision name='right_side_collision'>
        <pose>0 -0.20955 0 0 0 0</pose>
        <geometry>
          <box>
            <size>0.7493 0.0254 0.0508</size>
          </box>
        </geometry>
      </collision>

      <visual name='right_side_visual'>
        <pose>0 -0.20955 0 0 0 0</pose>
        <geometry>
          <box>
            <size>0.7493 0.0254 0.0508</size>
          </box>
        </geometry>
      </visual>

      <!--
        Front beams.  Centered around the origin.

        Dimensions:
        Length: 25 inches -> 0.635 meters
        Width: 1 inch -> 0.0254 meters
        Height: 2 inches -> 0.0508 meters
      -->
      <collision name='front_collision'>
        <pose>0.38735 0 0 0 0 1.5708</pose>
        <geometry>
          <box>
            <size>0.635 0.0254 0.0508</size>
          </box>
        </geometry>
      </collision>

      <visual name='front_visual'>
        <pose>0.38735 0 0 0 0 1.5708</pose>
        <geometry>
          <box>
            <size>0.635 0.0254 0.0508</size>
          </box>
        </geometry>
      </visual>

      <collision name='rear_collision'>
        <pose>-0.38735 0 0 0 0 1.5708</pose>
        <geometry>
          <box>
            <size>0.635 0.0254 0.0508</size>
          </box>
        </geometry>
      </collision>

      <visual name='rear_visual'>
        <pose>-0.38735 0 0 0 0 1.5708</pose>
        <geometry>
          <box>
            <size>0.635 0.0254 0.0508</size>
          </box>
        </geometry>
      </visual>

      <!--
        For visualization purposes a small cube will be added to the front of
        the robot.  No collision is used because the real robot does not have
        this cube.
      -->
      <visual name='cube_visual'>
        <pose>0.38735 0 0.0381 0 0 0</pose>
        <geometry>
          <box>
            <size>0.0254 0.0254 0.0254</size>
          </box>
        </geometry>
      </visual>
    </link>

    <!--
      Wheels.  Each of the 4 wheels have the following dimensions:

      Diameter: 6 inches -> 0.1524 meters
      Width: 1.775 inches -> 0.045085 meters

      There are two belts that connect each side's wheels together.
    -->
    <link name='left_front_wheel'>
      <pose>0.28575 0.2447925 0.0762 1.5708 0 0</pose>
      <inertial>
        <mass>0.36196671</mass>
        <inertia>
          <ixx>0.0005867</ixx>
          <iyy>0.0005867</iyy>
          <izz>0.0010509</izz>
          <ixy>0</ixy>
          <ixz>0</ixz>
          <iyz>0</iyz>
        </inertia>
      </inertial>

      <collision name='left_front_collision'>
        <geometry>
          <cylinder>
            <radius>0.0762</radius>
            <length>0.045085</length>
          </cylinder>
        </geometry>
      </collision>

      <visual name='left_front_visual'>
        <geometry>
          <cylinder>
            <radius>0.0762</radius>
            <length>0.045085</length>
          </cylinder>
        </geometry>
      </visual>
    </link>

    <link name='left_rear_wheel'>
      <pose>-0.28575 0.2447925 0.0762 1.5708 0 0</pose>
      <inertial>
        <mass>0.36196671</mass>
        <inertia>
          <ixx>0.0005867</ixx>
          <iyy>0.0005867</iyy>
          <izz>0.0010509</izz>
          <ixy>0</ixy>
          <ixz>0</ixz>
          <iyz>0</iyz>
        </inertia>
      </inertial>
      <collision name='left_rear_collision'>
        <geometry>
          <cylinder>
            <radius>0.0762</radius>
            <length>0.045085</length>
          </cylinder>
        </geometry>
      </collision>

      <visual name='left_rear_visual'>
        <geometry>
          <cylinder>
            <radius>0.0762</radius>
            <length>0.045085</length>
          </cylinder>
        </geometry>
      </visual>
    </link>

    <link name='right_front_wheel'>
      <pose>0.28575 -0.2447925 0.0762 1.5708 0 0</pose>
      <inertial>
        <mass>0.36196671</mass>
        <inertia>
          <ixx>0.0005867</ixx>
          <iyy>0.0005867</iyy>
          <izz>0.0010509</izz>
          <ixy>0</ixy>
          <ixz>0</ixz>
          <iyz>0</iyz>
        </inertia>
      </inertial>
      <collision name='right_front_collision'>
        <geometry>
          <cylinder>
            <radius>0.0762</radius>
            <length>0.045085</length>
          </cylinder>
        </geometry>
      </collision>

      <visual name='right_front_visual'>
        <geometry>
          <cylinder>
            <radius>0.0762</radius>
            <length>0.045085</length>
          </cylinder>
        </geometry>
      </visual>
    </link>

    <link name='right_rear_wheel'>
      <pose>-0.28575 -0.2447925 0.0762 1.5708 0 0</pose>
      <inertial>
        <mass>0.36196671</mass>
        <inertia>
          <ixx>0.0005867</ixx>
          <iyy>0.0005867</iyy>
          <izz>0.0010509</izz>
          <ixy>0</ixy>
          <ixz>0</ixz>
          <iyz>0</iyz>
        </inertia>
      </inertial>
      <collision name='right_rear_collision'>
        <geometry>
          <cylinder>
            <radius>0.0762</radius>
            <length>0.045085</length>
          </cylinder>
        </geometry>
      </collision>

      <visual name='right_rear_visual'>
        <geometry>
          <cylinder>
            <radius>0.0762</radius>
            <length>0.045085</length>
          </cylinder>
        </geometry>
      </visual>
    </link>

    <!-- Joints -->
    <joint type='revolute' name='left_front_hinge'>
      <pose>0 0 0.0762 0 0 0</pose>
      <child>left_front_wheel</child>
      <parent>chassis</parent>
      <axis>
        <xyz>0 1 0</xyz>
      </axis>
    </joint>

    <joint type='revolute' name='left_rear_hinge'>
      <pose>0 0 0.0762 0 0 0</pose>
      <child>left_rear_wheel</child>
      <parent>chassis</parent>
      <axis>
        <xyz>0 1 0</xyz>
      </axis>
    </joint>

    <joint type='revolute' name='right_front_hinge'>
      <pose>0 0 0.0762 0 0 0</pose>
      <child>right_front_wheel</child>
      <parent>chassis</parent>
      <axis>
        <xyz>0 1 0</xyz>
      </axis>
    </joint>

    <joint type='revolute' name='right_rear_hinge'>
      <pose>0 0 0.0762 0 0 0</pose>
      <child>right_rear_wheel</child>
      <parent>chassis</parent>
      <axis>
        <xyz>0 1 0</xyz>
      </axis>
      </joint>
  </model>
</sdf>
