<?xml version="1.0"?>
<robot xmlns:xacro="http://www.ros.org/wiki/xacro">
  <!-- Inertial Macros -->
  <xacro:macro name="inertial_box" params="mass x y z">
    <inertial>
      <mass value="${mass}"/>
      <inertia ixx="${(1/12) * mass * (y*y+z*z)}" ixy="0.0" ixz="0.0"
               iyy="${(1/12) * mass * (x*x+z*z)}" iyz="0.0"
               izz="${(1/12) * mass * (x*x+y*y)}"/>
    </inertial>
  </xacro:macro>

  <xacro:macro name="inertial_cylinder" params="mass length radius">
    <inertial>
      <mass value="${mass}"/>
      <inertia ixx="${(1/12) * mass * (3*radius*radius + length*length)}" ixy="0.0" ixz="0.0"
               iyy="${(1/12) * mass * (3*radius*radius + length*length)}" iyz="0.0"
               izz="${(1/2) * mass * (radius*radius)}"/>
    </inertial>
  </xacro:macro>

  <!--
    Robot mechanical dimensions.

    Main chassis frame consists of 2 side bars and 2 front/rear bars with the
    following dimensions:

    Side Bars:
    Length: 29.5 inches/0.7493 meters
    Width: 1 inch/0.0254 meters
    Height: 2 inches/0.0508 meters

    Front/Rear Bars:
    Length: 25 inches/0.635 meters
    Width: 1 inch/0.0254 meters
    Height: 2 inches/0.0508 meters

    Wheels:
    Diameter: 6 inches/0.1524 meters
    Width: 1.775 inches/0.045085 meters
  -->
  <xacro:property name="sidebar_length" value="0.7493"/>
  <xacro:property name="sidebar_width" value="0.0254"/>
  <xacro:property name="sidebar_height" value="0.0508"/>
  <xacro:property name="sidebar_y_offset" value="0.20955"/>

  <xacro:property name="frontbar_length" value="0.635"/>
  <xacro:property name="frontbar_width" value="0.0254"/>
  <xacro:property name="frontbar_height" value="0.0508"/>
  <xacro:property name="frontbar_x_offset" value="0.38735"/>

  <xacro:property name="wheel_radius" value="0.0762"/>
  <xacro:property name="wheel_width" value="0.045085"/>
  <xacro:property name="wheel_mass" value="0.36196671"/>
  <xacro:property name="wheel_x_offset" value="0.28575"/>
  <xacro:property name="wheel_y_offset" value="0.2447925"/>

  <xacro:property name="robot_mass" value="1.0"/>

  <!-- Macro to create the side bars -->
  <xacro:macro name="sidebar" params="prefix reflect">
    <visual name="${prefix}_side_visual">
      <origin xyz="0 ${sidebar_y_offset*reflect} 0" rpy="0 0 0"/>
      <geometry>
        <box size="${sidebar_length} ${sidebar_width} ${sidebar_height}"/>
      </geometry>
    </visual>
    <collision name="${prefix}_side_collision">
      <origin xyz="0 ${sidebar_y_offset*reflect} 0" rpy="0 0 0"/>
      <geometry>
        <box size="${sidebar_length} ${sidebar_width} ${sidebar_height}"/>
      </geometry>
    </collision>
  </xacro:macro>

  <!-- Macro to create the front/rear bars -->
  <xacro:macro name="frontbar" params="prefix reflect">
    <visual name="${prefix}_visual">
      <origin xyz="${frontbar_x_offset*reflect} 0 0" rpy="0 0 1.5708"/>
      <geometry>
        <box size="${frontbar_length} ${frontbar_width} ${frontbar_height}"/>
      </geometry>
    </visual>
    <collision name="${prefix}_collision">
      <origin xyz="${frontbar_x_offset*reflect} 0 0" rpy="0 0 1.5708"/>
      <geometry>
        <box size="${frontbar_length} ${frontbar_width} ${frontbar_height}"/>
      </geometry>
    </collision>
  </xacro:macro>

  <!-- Macro to create the wheels -->
  <xacro:macro name="wheel" params="prefix suffix reflectx reflecty">
    <link name="${prefix}_${suffix}_wheel">
      <xacro:inertial_cylinder mass="${wheel_mass}" length="${wheel_width}" radius="${wheel_radius}"/>
      <visual>
        <geometry>
          <cylinder length="${wheel_width}" radius="${wheel_radius}"/>
        </geometry>
       <material name="black"/>
      </visual>
      <collision>
        <geometry>
          <cylinder length="${wheel_width}" radius="${wheel_radius}"/>
        </geometry>
      </collision>
    </link>

    <!-- Joint connecting this wheel to the base_link -->
    <joint name="${prefix}_${suffix}_joint" type="continuous">
      <axis xyz="0 0 1" rpy="0 0 0"/>
      <parent link="base_link"/>
      <child link="${prefix}_${suffix}_wheel"/>
      <origin xyz="${reflectx*wheel_x_offset} ${reflecty*wheel_y_offset} 0.0"
              rpy="${-reflecty*pi/2} 0 0"/>
    </joint>
  </xacro:macro>

  <xacro:macro name="mimic_wheel" params="prefix suffix reflectx reflecty">
    <link name="${prefix}_${suffix}_wheel">
      <xacro:inertial_cylinder mass="${wheel_mass}" length="${wheel_width}" radius="${wheel_radius}"/>
      <visual>
        <geometry>
          <cylinder length="${wheel_width}" radius="${wheel_radius}"/>
        </geometry>
       <material name="black"/>
      </visual>
      <collision>
        <geometry>
          <cylinder length="${wheel_width}" radius="${wheel_radius}"/>
        </geometry>
      </collision>
    </link>

    <!-- Joint connecting this wheel to the base_link -->
    <joint name="${prefix}_${suffix}_joint" type="continuous">
      <axis xyz="0 0 1" rpy="0 0 0"/>
      <parent link="base_link"/>
      <child link="${prefix}_${suffix}_wheel"/>
      <origin xyz="${reflectx*wheel_x_offset} ${reflecty*wheel_y_offset} 0.0"
              rpy="${-reflecty*pi/2} 0 0"/>
      <mimic joint="${prefix}_front_joint" multiplier="1.0" offset="0.0"/>
    </joint>
  </xacro:macro>


  <material name="black">
    <color rgba="0 0 0 1"/>
  </material>

  <!-- Base Link -->
  <link name="base_link"/>

  <!-- Base Footprint Link -->
  <link name="base_footprint"/>

  <!-- Attach Base Link to Base Footprint -->
  <joint name="base_footprint_joint" type="fixed">
    <parent link="base_link"/>
    <child link="base_footprint"/>
    <origin xyz="0 0 0" rpy="0 0 0"/>
  </joint>

  <!-- Chassis represented by a 50 lbs cuboid (max weight limit) -->
  <link name="chassis">
    <!-- Left/Right sidebars -->
    <xacro:sidebar prefix="left" reflect="1"/>
    <xacro:sidebar prefix="right" reflect="-1"/>

    <!-- Front/Rear bars -->
    <xacro:frontbar prefix="front" reflect="1"/>
    <xacro:frontbar prefix="rear" reflect="-1"/>

    <!--
      For visualization purposes a small cube will be added to the front of the
      robot.  No collision is used because the real robot does not have this
      cube.
    -->
    <visual name="cube_visual">
      <geometry>
        <box size="0.0254 0.0254 0.0254"/>
      </geometry>
      <origin rpy="0 0 0" xyz="0.38735 0 0.0381"/>
    </visual>

    <xacro:inertial_box mass="${robot_mass}" x="${sidebar_length+2*frontbar_width}" y="${frontbar_length}" z="${sidebar_height}"/>
  </link>

  <!-- Attach chassis to Base Link -->
  <joint name="chassis_joint" type="fixed">
    <parent link="base_link"/>
    <child link="chassis"/>
  </joint>

  <!-- Wheels -->
  <xacro:wheel prefix="left" suffix="front" reflectx="1" reflecty="1"/>
  <xacro:mimic_wheel prefix="left" suffix="rear" reflectx="-1" reflecty="1"/>

  <xacro:wheel prefix="right" suffix="front" reflectx="1" reflecty="-1"/>
  <xacro:mimic_wheel prefix="right" suffix="rear" reflectx="-1" reflecty="-1"/>
</robot>
